<?xml version="1.0" ?>
<robot xmlns:xacro="http://www.ros.org/wiki/xacro">

    <xacro:macro name="sensor_mast" params="">

        <link name='chassis_to_mast_p'>
            <inertial>
                <origin xyz="0 0 0" rpy="0 0 0"/>
                <mass value="0.02"/>
                <inertia ixx="2.61666666667e-05" ixy="0.0" ixz="0.0" iyy="2.61666666667e-05" iyz="0.0" izz="3.6e-05"/>
            </inertial>
            <collision>
                <origin rpy="1.57 0 0" xyz="0 0 0"/>
                <geometry>
                    <cylinder radius="0.02" length="0.02"/>
                </geometry>
            </collision>
            <visual>
                <origin rpy="1.57 0 0" xyz="0 0 0"/>
                <geometry>
                    <cylinder radius="0.02" length="0.02"/>
                </geometry>
            </visual>
        </link>

        <joint name="chassis_to_mast_p_joint" type="fixed">
            <parent link="chassis"/>
            <child link="chassis_to_mast_p"/>
            <origin xyz="-0.55456 -0.722499 0.331395" rpy="0 0 0.523599"/>
        </joint>

        <link name='mast_p'>
            <collision>
                <origin xyz="0 0 0" rpy="0 0 0"/>
                <geometry>
                    <mesh filename="package://curiosity_mars_rover_description/meshes/mast_p_fixed.dae" scale="${scale_XYZ} ${scale_XYZ} ${scale_XYZ}"/>
                </geometry>
            </collision>

            <visual>
                <origin xyz="0 0 0" rpy="0 0 0"/>
                <geometry>
                    <mesh filename="package://curiosity_mars_rover_description/meshes/mast_p_fixed.dae" scale="${scale_XYZ} ${scale_XYZ} ${scale_XYZ}"/>
                </geometry>
            </visual>

            <inertial>
                <origin xyz="0 0 0" rpy="0 0 0"/>
                <mass value="${mast_p_Mass}"/>
                <xacro:box_inertia m="${mast_p_Mass}" x="${mast_p_X*scale_XYZ}" y="${mast_p_Y*scale_XYZ}" z="${mast_p_Z*scale_XYZ}"/>
            </inertial>
        </link>

        <joint name="mast_p_joint" type="revolute">
            <parent link="chassis_to_mast_p"/>
            <child link="mast_p"/>
            <origin xyz="0 0 0" rpy="0 0 0"/>
            <limit lower="${mast_p_lower_limit}" upper="${mast_p_upper_limit}" effort="10000.0" velocity="100.0"/>
            <axis xyz="0 1 0"/>
            <joint_properties damping="0.0" friction="0.0"/>
        </joint>

        <transmission name="mast_p_trans">
            <type>transmission_interface/SimpleTransmission</type>
            <joint name="mast_p_joint">
                <hardwareInterface>hardware_interface/EffortJointInterface</hardwareInterface>
            </joint>
            <actuator name="mast_pMotor">
                <hardwareInterface>hardware_interface/EffortJointInterface</hardwareInterface>
                <mechanicalReduction>1</mechanicalReduction>
            </actuator>
        </transmission>

        <link name='mast_p_to_mast_02'>
            <inertial>
                <origin xyz="0 0 0" rpy="0 0 0"/>
                <mass value="0.02"/>
                <inertia ixx="2.61666666667e-05" ixy="0.0" ixz="0.0" iyy="2.61666666667e-05" iyz="0.0" izz="3.6e-05"/>
            </inertial>
            <collision>
                <origin rpy="0 0 0" xyz="0 0 0"/>
                <geometry>
                    <cylinder radius="0.02" length="0.02"/>
                </geometry>
            </collision>
            <visual>
                <origin rpy="0 0 0" xyz="0 0 0"/>
                <geometry>
                    <cylinder radius="0.02" length="0.02"/>
                </geometry>
            </visual>
        </link>

        <joint name="mast_p_to_mast_02_joint" type="fixed">
            <parent link="mast_p"/>
            <child link="mast_p_to_mast_02"/>
            <origin xyz="0 0 0.473641" rpy="0 0 0"/>
        </joint>

        <link name='mast_02'>
            <collision>
                <origin xyz="0 0 0" rpy="0 0 0"/>
                <geometry>
                    <mesh filename="package://curiosity_mars_rover_description/meshes/mast_02_fixed.dae" scale="${scale_XYZ} ${scale_XYZ} ${scale_XYZ}"/>
                </geometry>
            </collision>

            <visual>
                <origin xyz="0 0 0" rpy="0 0 0"/>
                <geometry>
                    <mesh filename="package://curiosity_mars_rover_description/meshes/mast_02_fixed.dae" scale="${scale_XYZ} ${scale_XYZ} ${scale_XYZ}"/>
                </geometry>
            </visual>

            <inertial>
                <origin xyz="0 0 0" rpy="0 0 0"/>
                <mass value="${mast_02_Mass}"/>
                <xacro:box_inertia m="${mast_02_Mass}" x="${mast_02_X*scale_XYZ}" y="${mast_02_Y*scale_XYZ}" z="${mast_02_Z*scale_XYZ}"/>
            </inertial>
        </link>

        <joint name="mast_02_joint" type="continuous">
            <parent link="mast_p_to_mast_02"/>
            <child link="mast_02"/>
            <origin xyz="0 0 0" rpy="0 0 0"/>
            <limit effort="10000.0" velocity="100.0"/>
            <axis xyz="0 0 1"/>
            <joint_properties damping="0.0" friction="0.0"/>
        </joint>

        <transmission name="mast_02_trans">
            <type>transmission_interface/SimpleTransmission</type>
            <joint name="mast_02_joint">
                <hardwareInterface>hardware_interface/EffortJointInterface</hardwareInterface>
            </joint>
            <actuator name="mast_02Motor">
                <hardwareInterface>hardware_interface/EffortJointInterface</hardwareInterface>
                <mechanicalReduction>1</mechanicalReduction>
            </actuator>
        </transmission>

        <link name='mast_02_to_mast_cameras'>
            <inertial>
                <origin xyz="0 0 0" rpy="0 0 0"/>
                <mass value="0.02"/>
                <inertia ixx="2.61666666667e-05" ixy="0.0" ixz="0.0" iyy="2.61666666667e-05" iyz="0.0" izz="3.6e-05"/>
            </inertial>
            <collision>
                <origin rpy="0 0 0" xyz="0 0 0"/>
                <geometry>
                    <cylinder radius="0.02" length="0.02"/>
                </geometry>
            </collision>
            <visual>
                <origin rpy="0 0 0" xyz="0 0 0"/>
                <geometry>
                    <cylinder radius="0.02" length="0.02"/>
                </geometry>
            </visual>
        </link>

        <joint name="mast_02_to_mast_cameras_joint" type="fixed">
            <parent link="mast_02"/>
            <child link="mast_02_to_mast_cameras"/>
            <origin xyz="0 0 0.20859" rpy="0 0 0"/>
        </joint>

        <link name='mast_cameras'>
            <collision>
                <origin xyz="0 0 0" rpy="0 0 0"/>
                <geometry>
                    <mesh filename="package://curiosity_mars_rover_description/meshes/mast_cameras.dae" scale="${scale_XYZ} ${scale_XYZ} ${scale_XYZ}"/>
                </geometry>
            </collision>

            <visual>
                <origin xyz="0 0 0" rpy="0 0 0"/>
                <geometry>
                    <mesh filename="package://curiosity_mars_rover_description/meshes/mast_cameras.dae" scale="${scale_XYZ} ${scale_XYZ} ${scale_XYZ}"/>
                </geometry>
            </visual>

            <inertial>
                <origin xyz="0 0 0" rpy="0 0 0"/>
                <mass value="${mast_cameras_Mass}"/>
                <xacro:box_inertia m="${mast_cameras_Mass}" x="${mast_cameras_X*scale_XYZ}" y="${mast_cameras_Y*scale_XYZ}" z="${mast_cameras_Z*scale_XYZ}"/>
            </inertial>
        </link>

        <joint name="mast_cameras_joint" type="revolute">
            <parent link="mast_02_to_mast_cameras"/>
            <child link="mast_cameras"/>
            <origin xyz="0 0 0" rpy="0 0 0"/>
            <limit lower="${-mast_cameras_limit}" upper="${mast_cameras_limit}" effort="10000.0" velocity="100.0"/>
            <axis xyz="1 0 0"/>
            <joint_properties damping="0.0" friction="0.0"/>
        </joint>

        <transmission name="mast_02_trans">
            <type>transmission_interface/SimpleTransmission</type>
            <joint name="mast_cameras_joint">
                <hardwareInterface>hardware_interface/EffortJointInterface</hardwareInterface>
            </joint>
            <actuator name="mast_02Motor">
                <hardwareInterface>hardware_interface/EffortJointInterface</hardwareInterface>
                <mechanicalReduction>1</mechanicalReduction>
            </actuator>
        </transmission>

        <xacro:camera
            camera_name="chemcam"
            topic_name="chemcam"
            rot="-1.57079632679 0 3.141592653589793"
            pos="0.13642 -0.138683 0.222314"
            parent="mast_cameras"
			resolution_x="1024"
            resolution_y="1024"
            fov="1.3962634"
            format="R8G8B8"/>

        <xacro:unless value="$(arg simple_camera)">
            <xacro:camera
                camera_name="mastcam_left"
                topic_name="mastcam/left"
                rot="-1.57079632679 0 3.141592653589793"
                pos="0.145434 -0.138683 0.069"
                parent="mast_cameras"
                resolution_x="1600"
                resolution_y="1200"
                fov="0.261799"
                format="R8G8B8"/>

            <xacro:camera
                camera_name="mastcam_right"
                topic_name="mastcam/right"
                rot="-1.57079632679 0 3.141592653589793"
                pos="-0.099257 -0.138683 0.069"
                parent="mast_cameras"
                resolution_x="1600"
                resolution_y="1200"
                fov="0.0890118"
                format="R8G8B8"/>

            <xacro:if value="$(arg fake_depth)">
                <xacro:fake_depth_camera 
                        camera_name="navcam"
                        rot="-1.57079632679 0 3.141592653589793"
                        pos="0.232895 -0.138683 0.08503"
                        parent="mast_cameras"
                        resolution="1024"
                        fov="1.3962634"
                        baseline="0.419309"/>
            </xacro:if>

            <xacro:unless value="$(arg fake_depth)">
                <xacro:camera
                    camera_name="navcam_left"
                    topic_name="navcam/left"
                    rot="-1.57079632679 0 3.141592653589793"
                    pos="0.232895 -0.138683 0.08503"
                    parent="mast_cameras"
                    resolution_x="1024"
                    resolution_y="1024"
                    fov="1.3962634"
                    format="R8G8B8"/>

                <xacro:camera
                    camera_name="navcam_right"
                    topic_name="navcam/right"
                    rot="-1.57079632679 0 3.141592653589793"
                    pos="-0.186414 -0.138683 0.08503"
                    parent="mast_cameras"
                    resolution_x="1024"
                    resolution_y="1024"
                    fov="1.3962634"
                    format="R8G8B8"/>
            </xacro:unless>
        </xacro:unless>

    </xacro:macro>

</robot>
